Workbook
Name Slicer_Representative: #N/A

Sheet pivots
A3: Call Count | B3: Total Amount | C3: Total duration | D3: Avg Rating | E3: 5* Calls | H3: Rep Summary
A4: 1000 | B4: 96623 | C4: 89850 | D4: 3.8854 | E4: 307 | H4: % of calls | I4: =A11/A4 -> 0.207
H5: Calls | I5: =_xlfn.XLOOKUP(A50,E41:E45,F41:F45) -> 207
H6: Amount | I6: =_xlfn.XLOOKUP(A50,E41:E45,G41:G45) -> 20872
A10: Call Count | B10: Total Amount | C10: Total duration | D10: Avg Rating | E10: 5* Calls | H10: Call Rank | I10: =_xlfn.RANK.AVG(I5,F41:F45) -> 2
A11: 207 | B11: 20872 | C11: 17700 | D11: 3.8589372 | E11: 60 | H11: Amount Rank | I11: =_xlfn.RANK.AVG(I6,G41:G45) -> 1
H13: Labels
I14: ="% of calls:"&TEXT(I4,"0%") -> % of calls:21%
I15: =IF(COUNTA(A50:A54)>1,"","Call Rank:"&I10) -> Call Rank:2
I16: =IF(COUNTA(A50:A54)>1,"","Amount Rank:"&I11) -> Amount Rank:1
I17: =IF(COUNTA(A50:A54)>1,"",_xlfn.XLOOKUP(A50,Assets!E3:E7,Assets!F3:F7)) -> Mrs.Hima
A21: Row Labels | B21: Call Count | C21: Call Count2 | E21: Row Labels | F21: Call Count
A22: Jan | B22: 13 | C22: 13 | E22: Sunday | F22: 30
A23: Feb | B23: 13 | C23: 13 | E23: Monday | F23: 34
A24: Mar | B24: 28 | C24: 28 | E24: Tuesday | F24: 26
A25: Apr | B25: 24 | C25: 24 | E25: Wednesday | F25: 38
A26: May | B26: 23 | C26: 23 | E26: Thursday | F26: 27
A27: Jun | B27: 17 | C27: 17 | E27: Friday | F27: 27
A28: Jul | B28: 11 | C28: 11 | E28: Saturday | F28: 25
A29: Aug | B29: 11 | C29: 11 | E29: Grand Total | F29: 207
A30: Sep | B30: 14 | C30: 14
A31: Oct | B31: 30 | C31: 30
A32: Nov | B32: 14 | C32: 14
A33: Dec | B33: 9 | C33: 9
A34: Grand Total | B34: 207 | C34: 207
H38: Selected Rep | I38: =A50 -> R03
A39: Row Labels | B39: Call Count | C39: Total Amount | E39: For Graph
A40: R01 | B40: 189 | C40: 18415 | E40: Rep | F40: Calls | G40: Amount | H40: Sel. Calls | I40: Sel. Amount
A41: R02 | B41: 218 | C41: 20581 | E41: {=A40:C44} -> R01 | F41: 189 | G41: 18415 | H41: =IF(E41=$I$38, F41, NA()) -> #N/A | I41: =IF(E41=$I$38,G41,NA()) -> #N/A
A42: R03 | B42: 207 | C42: 20872 | E42: R02 | F42: 218 | G42: 20581 | H42: =IF(E42=$I$38, F42, NA()) -> #N/A | I42: =IF(E42=$I$38,G42,NA()) -> #N/A
A43: R04 | B43: 186 | C43: 16651 | E43: R03 | F43: 207 | G43: 20872 | H43: =IF(E43=$I$38, F43, NA()) -> 207 | I43: =IF(E43=$I$38,G43,NA()) -> 20872
A44: R05 | B44: 200 | C44: 20104 | E44: R04 | F44: 186 | G44: 16651 | H44: =IF(E44=$I$38, F44, NA()) -> #N/A | I44: =IF(E44=$I$38,G44,NA()) -> #N/A
A45: Grand Total | B45: 1000 | C45: 96623 | E45: R05 | F45: 200 | G45: 20104 | H45: =IF(E45=$I$38, F45, NA()) -> #N/A | I45: =IF(E45=$I$38,G45,NA()) -> #N/A
A49: Row Labels
A50: R03
A60: Call Count | B60: Column Labels
A61: Row Labels | B61: Female | C61: Male | D61: Grand Total
A62: Cincinnati | B62: 144 | C62: 132 | D62: 276
A63: Cleveland | B63: 326 | C63: 63 | D63: 389
A64: Columbus | B64: 129 | C64: 206 | D64: 335
...

Sheet Data
B1: Call Centre Data
B3: Call number | C3: Customer ID | D3: Duration | E3: Representative | F3: Date of Call | G3: Purchase Amount | H3: Satisfaction Rating | I3: FY | J3: Day of week | K3: Duration Bucket | L3: Rating rounded | Q3: Customer ID | R3: Gedner | S3: Age | T3: City
B4: Call_7271 | C4: C0003 | D4: 116 | E4: R05 | F4: 45658 | G4: 128 | H4: 4.9 | I4: =IF(MONTH(calls[[#This Row],[Date of Call]])<=6, YEAR(calls[[#This Row],[Date of Call]]), YEAR(calls[[#This Row],[Date of Call]])+1) -> 2025 | J4: =TEXT(calls[[#This Row],[Date of Call]],"DDDD") -> Wednesday | K4: {=_xlfn.IFS(calls[[#This Row],[Duration]]<=10,"Under 10 mins", calls[[#This Row],[Duration]]<=30, "10 to 30 mins", calls[[#This Row],[Duration]]<=60, "30 to 60 mins", calls[[#This Row],[Duration]]<=120, "1 to 2 hours", TRUE, "More than 2 hours")} -> 1 to 2 hours | L4: =ROUND(calls[[#This Row],[Satisfaction Rating]],0) -> 5 | Q4: C0001 | R4: Male | S4: 41 | T4: Columbus
B5: Call_7272 | C5: C0004 | D5: 119 | E5: R05 | F5: 45658 | G5: 135 | H5: 2.9 | I5: =IF(MONTH(calls[[#This Row],[Date of Call]])<=6, YEAR(calls[[#This Row],[Date of Call]]), YEAR(calls[[#This Row],[Date of Call]])+1) -> 2025 | J5: =TEXT(calls[[#This Row],[Date of Call]],"DDDD") -> Wednesday | K5: {=_xlfn.IFS(calls[[#This Row],[Duration]]<=10,"Under 10 mins", calls[[#This Row],[Duration]]<=30, "10 to 30 mins", calls[[#This Row],[Duration]]<=60, "30 to 60 mins", calls[[#This Row],[Duration]]<=120, "1 to 2 hours", TRUE, "More than 2 hours")} -> 1 to 2 hours | L5: =ROUND(calls[[#This Row],[Satisfaction Rating]],0) -> 3 | Q5: C0002 | R5: Male | S5: 31 | T5: Cleveland
B6: Call_7273 | C6: C0005 | D6: 68 | E6: R02 | F6: 45658 | G6: 66 | H6: 4.7 | I6: =IF(MONTH(calls[[#This Row],[Date of Call]])<=6, YEAR(calls[[#This Row],[Date of Call]]), YEAR(calls[[#This Row],[Date of Call]])+1) -> 2025 | J6: =TEXT(calls[[#This Row],[Date of Call]],"DDDD") -> Wednesday | K6: {=_xlfn.IFS(calls[[#This Row],[Duration]]<=10,"Under 10 mins", calls[[#This Row],[Duration]]<=30, "10 to 30 mins", calls[[#This Row],[Duration]]<=60, "30 to 60 mins", calls[[#This Row],[Duration]]<=120, "1 to 2 hours", TRUE, "More than 2 hours")} -> 1 to 2 hours | L6: =ROUND(calls[[#This Row],[Satisfaction Rating]],0) -> 5 | Q6: C0003 | R6: Male | S6: 26 | T6: Cincinnati
B7: Call_7274 | C7: C0014 | D7: 119 | E7: R02 | F7: 45658 | G7: 22 | H7: 2.9 | I7: =IF(MONTH(calls[[#This Row],[Date of Call]])<=6, YEAR(calls[[#This Row],[Date of Call]]), YEAR(calls[[#This Row],[Date of Call]])+1) -> 2025 | J7: =TEXT(calls[[#This Row],[Date of Call]],"DDDD") -> Wednesday | K7: {=_xlfn.IFS(calls[[#This Row],[Duration]]<=10,"Under 10 mins", calls[[#This Row],[Duration]]<=30, "10 to 30 mins", calls[[#This Row],[Duration]]<=60, "30 to 60 mins", calls[[#This Row],[Duration]]<=120, "1 to 2 hours", TRUE, "More than 2 hours")} -> 1 to 2 hours | L7: =ROUND(calls[[#This Row],[Satisfaction Rating]],0) -> 3 | Q7: C0004 | R7: Male | S7: 36 | T7: Cincinnati
B8: Call_7275 | C8: C0011 | D8: 128 | E8: R01 | F8: 45659 | G8: 31 | H8: 2.8 | I8: =IF(MONTH(calls[[#This Row],[Date of Call]])<=6, YEAR(calls[[#This Row],[Date of Call]]), YEAR(calls[[#This Row],[Date of Call]])+1) -> 2025 | J8: =TEXT(calls[[#This Row],[Date of Call]],"DDDD") -> Thursday | K8: {=_xlfn.IFS(calls[[#This Row],[Duration]]<=10,"Under 10 mins", calls[[#This Row],[Duration]]<=30, "10 to 30 mins", calls[[#This Row],[Duration]]<=60, "30 to 60 mins", calls[[#This Row],[Duration]]<=120, "1 to 2 hours", TRUE, "More than 2 hours")} -> More than 2 hours | L8: =ROUND(calls[[#This Row],[Satisfaction Rating]],0) -> 3 | Q8: C0005 | R8: Male | S8: 37 | T8: Columbus
B9: Call_7276 | C9: C0011 | D9: 49 | E9: R02 | F9: 45660 | G9: 135 | H9: 4.8 | I9: =IF(MONTH(calls[[#This Row],[Date of Call]])<=6, YEAR(calls[[#This Row],[Date of Call]]), YEAR(calls[[#This Row],[Date of Call]])+1) -> 2025 | J9: =TEXT(calls[[#This Row],[Date of Call]],"DDDD") -> Friday | K9: {=_xlfn.IFS(calls[[#This Row],[Duration]]<=10,"Under 10 mins", calls[[#This Row],[Duration]]<=30, "10 to 30 mins", calls[[#This Row],[Duration]]<=60, "30 to 60 mins", calls[[#This Row],[Duration]]<=120, "1 to 2 hours", TRUE, "More than 2 hours")} -> 30 to 60 mins | L9: =ROUND(calls[[#This Row],[Satisfaction Rating]],0) -> 5 | Q9: C0006 | R9: Male | S9: 23 | T9: Columbus
B10: Call_7277 | C10: C0007 | D10: 84 | E10: R05 | F10: 45660 | G10: 60 | H10: 4.7 | I10: =IF(MONTH(calls[[#This Row],[Date of Call]])<=6, YEAR(calls[[#This Row],[Date of Call]]), YEAR(calls[[#This Row],[Date of Call]])+1) -> 2025 | J10: =TEXT(calls[[#This Row],[Date of Call]],"DDDD") -> Friday | K10: {=_xlfn.IFS(calls[[#This Row],[Duration]]<=10,"Under 10 mins", calls[[#This Row],[Duration]]<=30, "10 to 30 mins", calls[[#This Row],[Duration]]<=60, "30 to 60 mins", calls[[#This Row],[Duration]]<=120, "1 to 2 hours", TRUE, "More than 2 hours")} -> 1 to 2 hours | L10: =ROUND(calls[[#This Row],[Satisfaction Rating]],0) -> 5 | Q10: C0007 | R10: Female | S10: 22 | T10: Cleveland
B11: Call_7278 | C11: C0003 | D11: 103 | E11: R04 | F11: 45660 | G11: 148 | H11: 4.4 | I11: =IF(MONTH(calls[[#This Row],[Date of Call]])<=6, YEAR(calls[[#This Row],[Date of Call]]), YEAR(calls[[#This Row],[Date of Call]])+1) -> 2025 | J11: =TEXT(calls[[#This Row],[Date of Call]],"DDDD") -> Friday | K11: {=_xlfn.IFS(calls[[#This Row],[Duration]]<=10,"Under 10 mins", calls[[#This Row],[Duration]]<=30, "10 to 30 mins", calls[[#This Row],[Duration]]<=60, "30 to 60 mins", calls[[#This Row],[Duration]]<=120, "1 to 2 hours", TRUE, "More than 2 hours")} -> 1 to 2 hours | L11: =ROUND(calls[[#This Row],[Satisfaction Rating]],0) -> 4 | Q11: C0008 | R11: Female | S11: 42 | T11: Cleveland
B12: Call_7279 | C12: C0005 | D12: 31 | E12: R02 | F12: 45660 | G12: 135 | H12: 3.6 | I12: =IF(MONTH(calls[[#This Row],[Date of Call]])<=6, YEAR(calls[[#This Row],[Date of Call]]), YEAR(calls[[#This Row],[Date of Call]])+1) -> 2025 | J12: =TEXT(calls[[#This Row],[Date of Call]],"DDDD") -> Friday | K12: {=_xlfn.IFS(calls[[#This Row],[Duration]]<=10,"Under 10 mins", calls[[#This Row],[Duration]]<=30, "10 to 30 mins", calls[[#This Row],[Duration]]<=60, "30 to 60 mins", calls[[#This Row],[Duration]]<=120, "1 to 2 hours", TRUE, "More than 2 hours")} -> 30 to 60 mins | L12: =ROUND(calls[[#This Row],[Satisfaction Rating]],0) -> 4 | Q12: C0009 | R12: Female | S12: 25 | T12: Columbus
B13: Call_7280 | C13: C0010 | D13: 44 | E13: R03 | F13: 45660 | G13: 105 | H13: 2.9 | I13: =IF(MONTH(calls[[#This Row],[Date of Call]])<=6, YEAR(calls[[#This Row],[Date of Call]]), YEAR(calls[[#This Row],[Date of Call]])+1) -> 2025 | J13: =TEXT(calls[[#This Row],[Date of Call]],"DDDD") -> Friday | K13: {=_xlfn.IFS(calls[[#This Row],[Duration]]<=10,"Under 10 mins", calls[[#This Row],[Duration]]<=30, "10 to 30 mins", calls[[#This Row],[Duration]]<=60, "30 to 60 mins", calls[[#This Row],[Duration]]<=120, "1 to 2 hours", TRUE, "More than 2 hours")} -> 30 to 60 mins | L13: =ROUND(calls[[#This Row],[Satisfaction Rating]],0) -> 3 | Q13: C0010 | R13: Female | S13: 30 | T13: Cleveland
B14: Call_7281 | C14: C0011 | D14: 102 | E14: R02 | F14: 45660 | G14: 69 | H14: 4.9 | I14: =IF(MONTH(calls[[#This Row],[Date of Call]])<=6, YEAR(calls[[#This Row],[Date of Call]]), YEAR(calls[[#This Row],[Date of Call]])+1) -> 2025 | J14: =TEXT(calls[[#This Row],[Date of Call]],"DDDD") -> Friday | K14: {=_xlfn.IFS(calls[[#This Row],[Duration]]<=10,"Under 10 mins", calls[[#This Row],[Duration]]<=30, "10 to 30 mins", calls[[#This Row],[Duration]]<=60, "30 to 60 mins", calls[[#This Row],[Duration]]<=120, "1 to 2 hours", TRUE, "More than 2 hours")} -> 1 to 2 hours | L14: =ROUND(calls[[#This Row],[Satisfaction Rating]],0) -> 5 | Q14: C0011 | R14: Female | S14: 30 | T14: Cincinnati
B15: Call_7282 | C15: C0013 | D15: 135 | E15: R05 | F15: 45660 | G15: 46 | H15: 3.4 | I15: =IF(MONTH(calls[[#This Row],[Date of Call]])<=6, YEAR(calls[[#This Row],[Date of Call]]), YEAR(calls[[#This Row],[Date of Call]])+1) -> 2025 | J15: =TEXT(calls[[#This Row],[Date of Call]],"DDDD") -> Friday | K15: {=_xlfn.IFS(calls[[#This Row],[Duration]]<=10,"Under 10 mins", calls[[#This Row],[Duration]]<=30, "10 to 30 mins", calls[[#This Row],[Duration]]<=60, "30 to 60 mins", calls[[#This Row],[Duration]]<=120, "1 to 2 hours", TRUE, "More than 2 hours")} -> More than 2 hours | L15: =ROUND(calls[[#This Row],[Satisfaction Rating]],0) -> 3 | Q15: C0012 | R15: Female | S15: 28 | T15: Cincinnati
... B18: Call_7285 | C18: C0013 | D18: 48 | E18: R01 | F18: 45661 | G18: 68 | H18: 4.9 | I18: =IF(MONTH(calls[[#This Row],[Date of Call]])<=6, YEAR(calls[[#This Row],[Date of Call]]), YEAR(calls[[#This Row],[Date of Call]])+1) -> 2025 | J18: =TEXT(calls[[#This Row],[Date of Call]],"DDDD") -> Saturday | K18: {=_xlfn.IFS(calls[[#This Row],[Duration]]<=10,"Under 10 mins", calls[[#This Row],[Duration]]<=30, "10 to 30 mins", calls[[#This Row],[Duration]]<=60, "30 to 60 mins", calls[[#This Row],[Duration]]<=120, "1 to 2 hours", TRUE, "More than 2 hours")} -> 30 to 60 mins | L18: =ROUND(calls[[#This Row],[Satisfaction Rating]],0) -> 5 | Q18: C0015 | R18: Female | S18: 43 | T18: Cleveland
B19: Call_7286 | C19: C0010 | D19: 176 | E19: R05 | F19: 45662 | G19: 24 | H19: 4.8 | I19: =IF(MONTH(calls[[#This Row],[Date of Call]])<=6, YEAR(calls[[#This Row],[Date of Call]]), YEAR(calls[[#This Row],[Date of Call]])+1) -> 2025 | J19: =TEXT(calls[[#This Row],[Date of Call]],"DDDD") -> Sunday | K19: {=_xlfn.IFS(calls[[#This Row],[Duration]]<=10,"Under 10 mins", calls[[#This Row],[Duration]]<=30, "10 to 30 mins", calls[[#This Row],[Duration]]<=60, "30 to 60 mins", calls[[#This Row],[Duration]]<=120, "1 to 2 hours", TRUE, "More than 2 hours")} -> More than 2 hours | L19: =ROUND(calls[[#This Row],[Satisfaction Rating]],0) -> 5
B20: Call_7287 | C20: C0010 | D20: 99 | E20: R01 | F20: 45662 | G20: 195 | H20: 3.9 | I20: =IF(MONTH(calls[[#This Row],[Date of Call]])<=6, YEAR(calls[[#This Row],[Date of Call]]), YEAR(calls[[#This Row],[Date of Call]])+1) -> 2025 | J20: =TEXT(calls[[#This Row],[Date of Call]],"DDDD") -> Sunday | K20: {=_xlfn.IFS(calls[[#This Row],[Duration]]<=10,"Under 10 mins", calls[[#This Row],[Duration]]<=30, "10 to 30 mins", calls[[#This Row],[Duration]]<=60, "30 to 60 mins", calls[[#This Row],[Duration]]<=120, "1 to 2 hours", TRUE, "More than 2 hours")} -> 1 to 2 hours | L20: =ROUND(calls[[#This Row],[Satisfaction Rating]],0) -> 4
B21: Call_7288 | C21: C0009 | D21: 28 | E21: R03 | F21: 45662 | G21: 28 | H21: 3.8 | I21: =IF(MONTH(calls[[#This Row],[Date of Call]])<=6, YEAR(calls[[#This Row],[Date of Call]]), YEAR(calls[[#This Row],[Date of Call]])+1) -> 2025 | J21: =TEXT(calls[[#This Row],[Date of Call]],"DDDD") -> Sunday | K21: {=_xlfn.IFS(calls[[#This Row],[Duration]]<=10,"Under 10 mins", calls[[#This Row],[Duration]]<=30, "10 to 30 mins", calls[[#This Row],[Duration]]<=60, "30 to 60 mins", calls[[#This Row],[Duration]]<=120, "1 to 2 hours", TRUE, "More than 2 hours")} -> 10 to 30 mins | L21: =ROUND(calls[[#This Row],[Satisfaction Rating]],0) -> 4
B22: Call_7289 | C22: C0007 | D22: 54 | E22: R02 | F22: 45662 | G22: 170 | H22: 4.3 | I22: =IF(MONTH(calls[[#This Row],[Date of Call]])<=6, YEAR(calls[[#This Row],[Date of Call]]), YEAR(calls[[#This Row],[Date of Call]])+1) -> 2025 | J22: =TEXT(calls[[#This Row],[Date of Call]],"DDDD") -> Sunday | K22: {=_xlfn.IFS(calls[[#This Row],[Duration]]<=10,"Under 10 mins", calls[[#This Row],[Duration]]<=30, "10 to 30 mins", calls[[#This Row],[Duration]]<=60, "30 to 60 mins", calls[[#This Row],[Duration]]<=120, "1 to 2 hours", TRUE, "More than 2 hours")} -> 30 to 60 mins | L22: =ROUND(calls[[#This Row],[Satisfaction Rating]],0) -> 4
B23: Call_7290 | C23: C0006 | D23: 48 | E23: R05 | F23: 45663 | G23: 30 | H23: 4.4 | I23: =IF(MONTH(calls[[#This Row],[Date of Call]])<=6, YEAR(calls[[#This Row],[Date of Call]]), YEAR(calls[[#This Row],[Date of Call]])+1) -> 2025 | J23: =TEXT(calls[[#This Row],[Date of Call]],"DDDD") -> Monday | K23: {=_xlfn.IFS(calls[[#This Row],[Duration]]<=10,"Under 10 mins", calls[[#This Row],[Duration]]<=30, "10 to 30 mins", calls[[#This Row],[Duration]]<=60, "30 to 60 mins", calls[[#This Row],[Duration]]<=120, "1 to 2 hours", TRUE, "More than 2 hours")} -> 30 to 60 mins | L23: =ROUND(calls[[#This Row],[Satisfaction Rating]],0) -> 4
B24: Call_7291 | C24: C0004 | D24: 128 | E24: R05 | F24: 45663 | G24: 72 | H24: 5 | I24: =IF(MONTH(calls[[#This Row],[Date of Call]])<=6, YEAR(calls[[#This Row],[Date of Call]]), YEAR(calls[[#This Row],[Date of Call]])+1) -> 2025 | J24: =TEXT(calls[[#This Row],[Date of Call]],"DDDD") -> Monday | K24: {=_xlfn.IFS(calls[[#This Row],[Duration]]<=10,"Under 10 mins", calls[[#This Row],[Duration]]<=30, "10 to 30 mins", calls[[#This Row],[Duration]]<=60, "30 to 60 mins", calls[[#This Row],[Duration]]<=120, "1 to 2 hours", TRUE, "More than 2 hours")} -> More than 2 hours | L24: =ROUND(calls[[#This Row],[Satisfaction Rating]],0) -> 5
B25: Call_7292 | C25: C0004 | D25: 38 | E25: R04 | F25: 45664 | G25: 92 | H25: 4.9 | I25: =IF(MONTH(calls[[#This Row],[Date of Call]])<=6, YEAR(calls[[#This Row],[Date of Call]]), YEAR(calls[[#This Row],[Date of Call]])+1) -> 2025 | J25: =TEXT(calls[[#This Row],[Date of Call]],"DDDD") -> Tuesday | K25: {=_xlfn.IFS(calls[[#This Row],[Duration]]<=10,"Under 10 mins", calls[[#This Row],[Duration]]<=30, "10 to 30 mins", calls[[#This Row],[Duration]]<=60, "30 to 60 mins", calls[[#This Row],[Duration]]<=120, "1 to 2 hours", TRUE, "More than 2 hours")} -> 30 to 60 mins | L25: =ROUND(calls[[#This Row],[Satisfaction Rating]],0) -> 5
B26: Call_7293 | C26: C0003 | D26: 67 | E26: R04 | F26: 45665 | G26: 165 | H26: 4.5 | I26: =IF(MONTH(calls[[#This Row],[Date of Call]])<=6, YEAR(calls[[#This Row],[Date of Call]]), YEAR(calls[[#This Row],[Date of Call]])+1) -> 2025 | J26: =TEXT(calls[[#This Row],[Date of Call]],"DDDD") -> Wednesday | K26: {=_xlfn.IFS(calls[[#This Row],[Duration]]<=10,"Under 10 mins", calls[[#This Row],[Duration]]<=30, "10 to 30 mins", calls[[#This Row],[Duration]]<=60, "30 to 60 mins", calls[[#This Row],[Duration]]<=120, "1 to 2 hours", TRUE, "More than 2 hours")} -> 1 to 2 hours | L26: =ROUND(calls[[#This Row],[Satisfaction Rating]],0) -> 5
B27: Call_7294 | C27: C0015 | D27: 58 | E27: R02 | F27: 45665 | G27: 140 | H27: 2.1 | I27: =IF(MONTH(calls[[#This Row],[Date of Call]])<=6, YEAR(calls[[#This Row],[Date of Call]]), YEAR(calls[[#This Row],[Date of Call]])+1) -> 2025 | J27: =TEXT(calls[[#This Row],[Date of Call]],"DDDD") -> Wednesday | K27: {=_xlfn.IFS(calls[[#This Row],[Duration]]<=10,"Under 10 mins", calls[[#This Row],[Duration]]<=30, "10 to 30 mins", calls[[#This Row],[Duration]]<=60, "30 to 60 mins", calls[[#This Row],[Duration]]<=120, "1 to 2 hours", TRUE, "More than 2 hours")} -> 30 to 60 mins | L27: =ROUND(calls[[#This Row],[Satisfaction Rating]],0) -> 2
B28: Call_7295 | C28: C0010 | D28: 54 | E28: R01 | F28: 45665 | G28: 111 | H28: 3.3 | I28: =IF(MONTH(calls[[#This Row],[Date of Call]])<=6, YEAR(calls[[#This Row],[Date of Call]]), YEAR(calls[[#This Row],[Date of Call]])+1) -> 2025 | J28: =TEXT(calls[[#This Row],[Date of Call]],"DDDD") -> Wednesday | K28: {=_xlfn.IFS(calls[[#This Row],[Duration]]<=10,"Under 10 mins", calls[[#This Row],[Duration]]<=30, "10 to 30 mins", calls[[#This Row],[Duration]]<=60, "30 to 60 mins", calls[[#This Row],[Duration]]<=120, "1 to 2 hours", TRUE, "More than 2 hours")} -> 30 to 60 mins | L28: =ROUND(calls[[#This Row],[Satisfaction Rating]],0) -> 3
B29: Call_7296 | C29: C0012 | D29: 28 | E29: R05 | F29: 45666 | G29: 63 | H29: 4.1 | I29: =IF(MONTH(calls[[#This Row],[Date of Call]])<=6, YEAR(calls[[#This Row],[Date of Call]]), YEAR(calls[[#This Row],[Date of Call]])+1) -> 2025 | J29: =TEXT(calls[[#This Row],[Date of Call]],"DDDD") -> Thursday | K29: {=_xlfn.IFS(calls[[#This Row],[Duration]]<=10,"Under 10 mins", calls[[#This Row],[Duration]]<=30, "10 to 30 mins", calls[[#This Row],[Duration]]<=60, "30 to 60 mins", calls[[#This Row],[Duration]]<=120, "1 to 2 hours", TRUE, "More than 2 hours")} -> 10 to 30 mins | L29: =ROUND(calls[[#This Row],[Satisfaction Rating]],0) -> 4
B30: Call_7297 | C30: C0002 | D30: 73 | E30: R05 | F30: 45666 | G30: 80 | H30: 4.2 | I30: =IF(MONTH(calls[[#This Row],[Date of Call]])<=6, YEAR(calls[[#This Row],[Date of Call]]), YEAR(calls[[#This Row],[Date of Call]])+1) -> 2025 | J30: =TEXT(calls[[#This Row],[Date of Call]],"DDDD") -> Thursday | K30: {=_xlfn.IFS(calls[[#This Row],[Duration]]<=10,"Under 10 mins", calls[[#This Row],[Duration]]<=30, "10 to 30 mins", calls[[#This Row],[Duration]]<=60, "30 to 60 mins", calls[[#This Row],[Duration]]<=120, "1 to 2 hours", TRUE, "More than 2 hours")} -> 1 to 2 hours | L30: =ROUND(calls[[#This Row],[Satisfaction Rating]],0) -> 4
... B1003: Call_8270 | C1003: C0009 | D1003: 114 | E1003: R01 | F1003: 46022 | G1003: 40 | H1003: 3.9 | I1003: =IF(MONTH(calls[[#This Row],[Date of Call]])<=6, YEAR(calls[[#This Row],[Date of Call]]), YEAR(calls[[#This Row],[Date of Call]])+1) -> 2026 | J1003: =TEXT(calls[[#This Row],[Date of Call]],"DDDD") -> Wednesday | K1003: {=_xlfn.IFS(calls[[#This Row],[Duration]]<=10,"Under 10 mins", calls[[#This Row],[Duration]]<=30, "10 to 30 mins", calls[[#This Row],[Duration]]<=60, "30 to 60 mins", calls[[#This Row],[Duration]]<=120, "1 to 2 hours", TRUE, "More than 2 hours")} -> 1 to 2 hours | L1003: =ROUND(calls[[#This Row],[Satisfaction Rating]],0) -> 4

Sheet customer centre report
P16: {=pivots!B82:F82} -> R01 | Q16: R02 | R16: R03 | S16: R04 | T16: R05 | U16: =pivots!G82 -> Grand Total
O17: {=IF(pivots!A83:G100="","",pivots!A83:G100)} -> Cincinnati
O18: C0003 | P18: 891 | Q18: 1332 | R18: 1282 | S18: 739 | T18: 560 | U18: 4804
O19: C0004 | P19: 1991 | Q19: 1886 | R19: 1206 | S19: 884 | T19: 1722 | U19: 7689
O20: C0011 | P20: 1163 | Q20: 1180 | R20: 1616 | S20: 1043 | T20: 1747 | U20: 6749
O21: C0012 | P21: 1438 | Q21: 1616 | R21: 866 | S21: 829 | T21: 2070 | U21: 6819
O22: Cleveland
O23: C0002 | P23: 1233 | Q23: 223 | R23: 1680 | S23: 990 | T23: 1508 | U23: 5634
O24: C0007 | P24: 1598 | Q24: 1907 | R24: 869 | S24: 1426 | T24: 1416 | U24: 7216
O25: C0008 | P25: 900 | Q25: 1016 | R25: 960 | S25: 940 | T25: 1193 | U25: 5009
O26: C0010 | P26: 900 | Q26: 1470 | R26: 1617 | S26: 1314 | T26: 941 | U26: 6242
O27: C0013 | P27: 1255 | Q27: 516 | R27: 1874 | S27: 1863 | T27: 1722 | U27: 7230
O28: C0015 | P28: 1138 | Q28: 1898 | R28: 1482 | S28: 846 | T28: 1154 | U28: 6518
M29: =pivots!I17 -> Mrs.Hima | O29: Columbus
M30: =pivots!I14 -> % of calls:21% | O30: C0001 | P30: 1655 | Q30: 805 | R30: 2263 | S30: 987 | T30: 1075 | U30: 6785
M31: =pivots!I15 -> Call Rank:2 | O31: C0005 | P31: 1104 | Q31: 2280 | R31: 1445 | S31: 1722 | T31: 1196 | U31: 7747
M32: =pivots!I16 -> Amount Rank:1 | O32: C0006 | P32: 372 | Q32: 1818 | R32: 1346 | S32: 1156 | T32: 1484 | U32: 6176
O33: C0009 | P33: 1415 | Q33: 1271 | R33: 1214 | S33: 1135 | T33: 1566 | U33: 6601
O34: C0014 | P34: 1362 | Q34: 1363 | R34: 1152 | S34: 777 | T34: 750 | U34: 5404

Sheet Assets
E2: Rep ID | F2: Rep Image
E3: R01 | F3: Mrs. Tina
E4: R02 | F4: Mrs.Rita
E5: R03 | F5: Mrs.Hima
E6: R04 | F6: Mr. Mahesh
E7: R05 | F7: Mr. Rakesh
